Workbook

Sheet FRONT PAGE
A14: India’s largest producer of zinc, lead, and silver
A15: Subsidiary of Vedanta Limited
A16: Operates integrated mining and smelting units mainly in Rajasthan
A17: Supplies metals to construction, automobile, infrastructure, and electronics industries
A18: Known for low production cost, strong profits, and high dividend payouts
A19: Major player in India’s non-ferrous metals sector
A22: Company Name: Hindustan Zinc Limited
A23: Company Symbol (Ticker): HINDZINC
A24: ISIN: INE267A01025
A25: Industry: Metals & Mining
A26: Sector: Non-Ferrous Metals
A27: Stock Exchange (Shares Listed): NSE, BSE
... A41: Primary Shares Outstanding (cr): 422

Sheet SUMMARY TABLES
A2: P&L SMMARY
A3: Year | B3: Revenue | C3: EBITDA | D3: EBIT | E3: PAT
A4: 2021 | B4: 22071 | C4: 15844 | D4: 15132 | E4: 12152
A5: 2022 | B5: 28790 | C5: 15575 | D5: 13877 | E5: 9116
A6: 2023 | B6: 33272 | C6: 16680 | D6: 14795 | E6: 9685
A7: 2024 | B7: 28082 | C7: 12806 | D7: 10412 | E7: 6909
A8: 2025 | B8: 33041 | C8: 16346 | D8: 13689 | E8: 9394
A9: 2026E | B9: 39019 | C9: 19483 | D9: -1041 | E9: -1507
A10: 2027E | B10: 62511 | C10: 31160 | D10: 27705 | E10: 20591
A12: PROFITABLITY SUMMARY
A13: Year | B13: EBITDA % | C13: EBIT % | D13: Net Margin %
A14: 2021 | B14: 0.718 | C14: 0.686 | D14: 0.551
A15: 2022 | B15: 0.541 | C15: 0.482 | D15: 0.317
A16: 2023 | B16: 0.501 | C16: 0.445 | D16: 0.291
A17: 2024 | B17: 0.456 | C17: 0.371 | D17: 0.246
A18: 2025 | B18: 0.495 | C18: 0.414 | D18: 0.284
A19: 2026E | B19: 0.499
A20: 2027E | B20: 0.498 | C20: 0.443 | D20: 0.329
A22: BALANCE SHEET SUMMARY (IN Cr)
A23: Year | B23: Total Assets | C23: Equity | D23: Liabilities
A24: 2021 | B24: 36126 | C24: 25361 | D24: 36126
A25: 2022 | B25: 41824 | C25: 28269 | D25: 41824
A26: 2023 | B26: 47512 | C26: 31874 | D26: 47512
A27: 2024 | B27: 51364 | C27: 34217 | D27: 51364
A28: 2025 | B28: 56772 | C28: 37985 | D28: 56772
A29: 2026E | B29: 63984 | C29: 41765 | D29: 63984
A30: 2027E | B30: 71908 | C30: 46153 | D30: 71908
A32: CASH FLOW SUMMARY (IN Cr)
A33: Year | B33: Operating CF | C33: Investing CF | D33: Financing CF | E33: Net Change
A34: 2021 | B34: Strong positive | C34: Negative (capex) | D34: Negative (dividends) | E34: Stable
A35: 2022 | B35: Strong positive | C35: Negative | D35: Negative | E35: Stable
A36: 2023 | B36: Strong positive | C36: Negative | D36: Negative | E36: Slight drop
A37: 2024 | B37: Moderate | C37: Capex heavy | D37: Dividend heavy | E37: Lower cash
A38: 2025 | B38: Recovery | C38: Capex continues | D38: Dividend payout | E38: Stable
A39: 2026E | B39: Improving | C39: Expansion capex | D39: Financing support | E39: Growth
A40: 2027E | B40: Very strong | C40: Expansion investment | D40: Stable | E40: Strong rise
A42: GROWTH SUMMARY
A43: Year | B43: Revenue Growth | C43: PAT Growth
A44: 2022 | B44: 0.304 | C44: -0.25
A45: 2023 | B45: 0.156 | C45: 0.062
...

Sheet CHARTS
A2: FINANCIAL DATA CHARTS
A3: Particular | B3: 2021 | C3: 2022 | D3: 2023 | E3: 2024 | F3: 2025 | G3: 2026E | H3: 2027E
A4: Revenue | B4: 22071 | C4: 28790 | D4: 33272 | E4: 28082 | F4: 33041 | G4: 39019 | H4: 62511
A5: Revenue Growth % | B5: — | C5: 0.304 | D5: 0.156 | E5: -0.156 | F5: 0.177 | G5: 0.181 | H5: 0.602
A6: EBITDA | B6: 15844 | C6: 15575 | D6: 16680 | E6: 12806 | F6: 16346 | G6: 19483 | H6: 31160
A7: EBITDA Margin % | B7: 0.718 | C7: 0.541 | D7: 0.501 | E7: 0.456 | F7: 0.495 | G7: 0.499 | H7: 0.498
A8: EBIT | B8: 15132 | C8: 13877 | D8: 14795 | E8: 10412 | F8: 13689 | G8: -1041 | H8: 27705
A9: EBIT Margin % | B9: 0.686 | C9: 0.482 | D9: 0.445 | E9: 0.371 | F9: 0.414 | G9: __ | H9: 0.443
A10: Net Profit | B10: 12152 | C10: 9116 | D10: 9685 | E10: 6909 | F10: 9394 | G10: -1507 | H10: 20591
A11: Net Margin % | B11: 0.551 | C11: 0.317 | D11: 0.291 | E11: 0.246 | F11: 0.284 | G11: NEG | H11: 0.329

Sheet P&L 
A2: Hindustan Zinc | B2: 44286 | C2: 44651 | D2: 45016 | E2: 45382 | F2: 45747 | G2: 46112 | H2: 46477
A3: Profit & Loss Account | B3: Y | C3: Y | D3: Y | E3: Y | F3: Y | G3: Y | H3: Y
A4: (in INR Crores) | B4: Act | C4: Act | D4: Act | E4: Act | F4: Act | G4: Est | H4: Est
A6: Revenue from operations | B6: 22071 | C6: 28790 | D6: 33272 | E6: 28082 | F6: 33041 | G6: ='Revenue model'!G15 -> 3901.9 | H6: ='Revenue model'!H15 -> 62510.717
A7: Excise duty | B7: 0 | C7: 0 | D7: 0 | E7: 0 | F7: 0 | G7: 0 | H7: 0 | K7: Revenue trend shows long-term growth with temporary dips → business demand is stable but cyclical.
A8: Net Revenue | B8: =B6-B7 -> 22071 | C8: =C6-C7 -> 28790 | D8: =D6-D7 -> 33272 | E8: =E6-E7 -> 28082 | F8: =F6-F7 -> 33041 | G8: =G6-G7 -> 3901.9 | H8: =H6-H7 -> 62510.717 | K8: Costs (power, royalty, fuel) are rising → margins depend on commodity prices and efficiency
K9: Strong EBITDA history → high operating leverage.
A10: Cost of Goods Sold | B10: =B11+B12+B13 -> 4730 | C10: =C11+C12+C13 -> 5841 | D10: =D11+D12+D13 -> 7636 | E10: =E11+E12+E13 -> 6203 | F10: =F11+F12+F13 -> 6741 | G10: =G11+G12+G13 -> 836.25651 | H10: =H11+H12+H13 -> 13397.467 | K10: Increasing depreciation → ongoing expansion/capex.
A11: Power and fuel | B11: 1732 | C11: 2452 | D11: 3711 | E11: 2843 | F11: 2702 | G11: =G38 -> 357.56552 | H11: =H38 -> 5892.9968 | K11: Debt costs stable → financial risk controlled
A12: Mining Royalty | B12: 2759 | C12: 3667 | D12: 4068 | E12: 3517 | F12: 4103 | G12: =G41 -> 487.00446 | H12: =H41 -> 7799.6763 | K12: Overall: Strong fundamentals, cyclical earnings, positive long-term outlook with short-term volatility.
A13: Changes in inventories of finished goods | B13: 239 | C13: -278 | D13: -143 | E13: -157 | F13: -64 | G13: =G44 -> -8.3134715 | H13: =H44 -> -295.20583
A14: Gross Profit | B14: =B8-B1 -> 22071 | C14: =C8-C10 -> 22949 | D14: =D8-D10 -> 25636 | E14: =E8-E10 -> 21879 | F14: =F8-F10 -> 26300 | G14: =G8-G10 -> 3065.6435 | H14: =H8-H10 -> 49113.249
A16: Selling & General Adm Expenses
A17: Employee benefits expense | B17: 760 | C17: 718 | D17: 845 | E17: 828 | F17: 886 | G17: =G47 -> 110.08861 | H17: =H47 -> 1685.9177
A18: Other expenses | B18: 5467 | C18: 6656 | D18: 8111 | E18: 8245 | F18: 9068 | G18: =G50 -> 1007.2535 | H18: =H50 -> 16267.36
A19: EBITDA | B19: =B14-B17-B18 -> 15844 | C19: =C14-C17-C18 -> 15575 | D19: =D14-D17-D18 -> 16680 | E19: =E14-E17-E18 -> 12806 | F19: =F14-F17-F18 -> 16346 | G19: =G14-G17-G18 -> 1948.3013 | H19: =H14-H17-H18 -> 31159.972
A21: Other income | B21: 1819 | C21: 1216 | D21: 1379 | E21: 1074 | F21: 983 | G21: =G22*('Balance sheet'!G12+'Balance sheet'!G24) -> 1114.7611 | H21: =H22*('Balance sheet'!H12+'Balance sheet'!H24) -> 1057.7246 | I21: based on investment
A22: % of investment | B22: =B21/('Balance sheet'!B12+'Balance sheet'!B24) -> 0.14038744 | C22: =C21/('Balance sheet'!C12+'Balance sheet'!C24) -> 0.080786606 | D22: =D21/('Balance sheet'!D12+'Balance sheet'!D24) -> 0.13644009 | E22: =E21/('Balance sheet'!E12+'Balance sheet'!E24) -> 0.10275545 | F22: =F21/('Balance sheet'!F12+'Balance sheet'!F24) -> 0.098576013 | G22: =AVERAGE(B22:F22) -> 0.11178912 | H22: =AVERAGE(C22:G22) -> 0.10606946
A23: Depreciation and amortization expense | B23: 2531 | C23: 2914 | D23: 3264 | E23: 3468 | F23: 3640 | G23: =G24*'Capex model'!G6 -> 4103.6177 | H23: =H24*'Capex model'!H6 -> 4512.8743 | I23: based on FA
A24: % of Gross Block | B24: =B23/'Capex model'!B6 -> 0.079473734 | C24: =C23/'Capex model'!C6 -> 0.083169221 | D24: =D23/'Capex model'!D6 -> 0.085865362 | E24: =E23/'Capex model'!E6 -> 0.083141542 | F24: =F23/'Capex model'!F6 -> 0.079850828 | G24: =AVERAGE(B24:F24) -> 0.082300137 | H24: =AVERAGE(C24:G24) -> 0.082865418
A25: EBIT | B25: =B19+B21-B23 -> 15132 | C25: =C19+C21-C23 -> 13877 | D25: =D19+D21-D23 -> 14795 | E25: =E19+E21-E23 -> 10412 | F25: =F19+F21-F23 -> 13689 | G25: =G19+G21-G23 -> -1040.5552 | H25: =H19+H21-H23 -> 27704.822
A27: Finance costs | B27: 386 | C27: 290 | D27: 333 | E27: 955 | F27: 1095 | G27: =G28*('Balance sheet'!G45+'Balance sheet'!G46+'Balance sheet'!G55+'Balance sheet'!G56) -> 875.09541 | H27: =H28*('Balance sheet'!H45+'Balance sheet'!H46+'Balance sheet'!H55+'Balance sheet'!H56) -> 919.31697 | I27: Based on browwoings & lease
A28: % of borowwings & lease | B28: =B27/('Balance sheet'!B45+'Balance sheet'!B46+'Balance sheet'!B55+'Balance sheet'!B56) -> 0.059632319 | C28: =C27/('Balance sheet'!C45+'Balance sheet'!C46+'Balance sheet'!C55+'Balance sheet'!C56) -> 0.10196906 | D28: =D27/('Balance sheet'!D45+'Balance sheet'!D46+'Balance sheet'!D55+'Balance sheet'!D56) -> 0.028027944 | E28: =E27/('Balance sheet'!E45+'Balance sheet'!E46+'Balance sheet'!E55+'Balance sheet'!E56) -> 0.10949324 | F28: =F27/('Balance sheet'!F45+'Balance sheet'!F46+'Balance sheet'!F55+'Balance sheet'!F56) -> 0.09984499 | G28: =AVERAGE(B28:F28) -> 0.079793509 | H28: =AVERAGE(C28:G28) -> 0.083825747
A29: PBT | B29: =B25-B27 -> 14746 | C29: =C25-C27 -> 13587 | D29: =D25-D27 -> 14462 | E29: =E25-E27 -> 9457 | F29: =F25-F27 -> 12594 | G29: =G25-G27 -> -1915.6506 | H29: =H25-H27 -> 26785.505
A31: Current tax | B31: 1827 | C31: 2445 | D31: 3431 | E31: 2549 | F31: 3226 | G31: =G32*G29 -> -408.71608 | H31: =H32*H29 -> 6194.0926
A32: % of PBT | B32: =B31/B29 -> 0.12389801 | C32: =C31/C29 -> 0.17995142 | D32: =D31/D29 -> 0.23724243 | E32: =E31/E29 -> 0.26953579 | F32: =F31/F29 -> 0.25615372 | G32: =AVERAGE(B32:F32) -> 0.21335628 | H32: =AVERAGE(C32:G32) -> 0.23124793
A33: Deferred tax | B33: 767 | C33: 2026 | D33: 1346 | E33: -1 | F33: -26 | G33: 0 | H33: 0 | I33: Uncertain
A34: PAT | B34: =B29-B31-B33 -> 12152 | C34: =C29-C31-C33 -> 9116 | D34: =D29-D31-D33 -> 9685 | E34: =E29-E31-E33 -> 6909 | F34: =F29-F31-F33 -> 9394 | G34: =G29-G31-G33 -> -1506.9346 | H34: =H29-H31-H33 -> 20591.413
A36: ASSUMTIONS
A38: =A11 -> Power and fuel | B38: =B11 -> 1732 | C38: =C11 -> 2452 | D38: =D11 -> 3711 | E38: =E11 -> 2843 | F38: =F11 -> 2702 | G38: =G39*G8 -> 357.56552 | H38: =H39*H8 -> 5892.9968
A39: % of Net Revenue | B39: =B38/B8 -> 0.078474016 | C39: =C38/C8 -> 0.085168461 | D39: =D38/D8 -> 0.11153522 | E39: =E38/E8 -> 0.10123923 | F39: =F38/F8 -> 0.081777186 | G39: =AVERAGE(B39:F39) -> 0.091638823 | H39: =AVERAGE(C39:G39) -> 0.094271785
A41: =A12 -> Mining Royalty | B41: =B12 -> 2759 | C41: =C12 -> 3667 | D41: =D12 -> 4068 | E41: =E12 -> 3517 | F41: =F12 -> 4103 | G41: =G42*G8 -> 487.00446 | H41: =H42*H8 -> 7799.6763
A42: % of Net Revenue | B42: =B41/B8 -> 0.12500566 | C42: =C41/C8 -> 0.12737061 | D42: =D41/D8 -> 0.12226497 | E42: =E41/E8 -> 0.12524037 | F42: =F41/F8 -> 0.12417905 | G42: =AVERAGE(B42:F42) -> 0.12481213 | H42: =AVERAGE(C42:G42) -> 0.12477343
A44: =A13 -> Changes in inventories of finished goods | B44: =B13 -> 239 | C44: =C13 -> -278 | D44: =D13 -> -143 | E44: =E13 -> -157 | F44: =F13 -> -64 | G44: =G45*G8 -> -8.3134715 | H44: =H45*H8 -> -295.20583
A45: % of Net Revenue | B45: =B44/B8 -> 0.010828689 | C45: =C44/C8 -> -0.0096561306 | D45: =D44/D8 -> -0.0042979082 | E45: =E44/E8 -> -0.0055907699 | F45: =F44/F8 -> -0.0019369874 | G45: =AVERAGE(B45:F45) -> -0.0021306214 | H45: =AVERAGE(C45:G45) -> -0.0047224835
A47: =A17 -> Employee benefits expense | B47: =B17 -> 760 | C47: =C17 -> 718 | D47: =D17 -> 845 | E47: =E17 -> 828 | F47: =F17 -> 886 | G47: =G48*G8 -> 110.08861 | H47: =H48*H8 -> 1685.9177
A48: % of Net Revenue | B48: =B47/B8 -> 0.034434326 | C48: =C47/C8 -> 0.024939215 | D48: =D47/D8 -> 0.02539673 | E48: =E47/E8 -> 0.029485079 | F48: =F47/F8 -> 0.026815169 | G48: =AVERAGE(B48:F48) -> 0.028214104 | H48: =AVERAGE(C48:G48) -> 0.026970059
A50: =A18 -> Other expenses | B50: =B18 -> 5467 | C50: =C18 -> 6656 | D50: =D18 -> 8111 | E50: =E18 -> 8245 | F50: =F18 -> 9068 | G50: =G51*G8 -> 1007.2535 | H50: =H51*H8 -> 16267.36
A51: % of Net Revenue | B51: =B50/B8 -> 0.2477006 | C51: =C50/C8 -> 0.23119139 | D51: =D50/D8 -> 0.24377855 | E51: =E50/E8 -> 0.29360444 | F51: =F50/F8 -> 0.2744469 | G51: =AVERAGE(B51:F51) -> 0.25814438 | H51: =AVERAGE(C51:G51) -> 0.26023313

Sheet Balance sheet
A2: Hindustan Zinc | B2: 44286 | C2: 44651 | D2: 45016 | E2: 45382 | F2: 45747 | G2: 46112 | H2: 46477
A3: Balance Sheet | B3: Y | C3: Y | D3: Y | E3: Y | F3: Y | G3: Y | H3: Y
A4: (in INR Crores) | B4: Act | C4: Act | D4: Act | E4: Act | F4: Act | G4: Est | H4: Est
A6: ASSETS
A7: Non-current asset | K7: Always Forcast | M7: no forecast
A8: Property, plant and equipment | B8: 16447 | C8: 17165 | D8: 17530 | E8: 17971 | F8: 18485 | G8: ='Capex model'!G9 -> 18657.996 | H8: ='Capex model'!H9 -> 18743.794 | K8: most imp | L8: moderate imp | M8: Least imp
A9: Capital work-in-progress | B9: 1922 | C9: 2075 | D9: 2237 | E9: 1696 | F9: 2606 | G9: =F9 -> 2606 | H9: =G9 -> 2606 | K9: PPE | L9: CWIP | M9: All remaining items expect moderate & most
A10: Intangible Assets | B10: 361 | C10: 231 | D10: 92 | E10: 180 | F10: 123 | G10: =F10 -> 123 | H10: =G10 -> 123 | K10: Inventories | L10: Investments
A11: Financial assets | K11: Trade Rec | L11: Loan given
A12: Investments | B12: 0 | C12: 0 | D12: 257 | E12: 578 | F12: 823 | G12: =F12 -> 823 | H12: =G12 -> 823 | I12: based on news | K12: Other equity | L12: Equity Share Capital
A13: Loans | B13: 12 | C13: 2 | D13: 0 | E13: 0 | F13: 1 | G13: =F13 -> 1 | H13: =G13 -> 1 | I13: based on news | K13: Trade Payable | L13: Borrowoings & lease
A14: Others | B14: 43 | C14: 56 | D14: 112 | E14: 131 | F14: 95 | G14: =F14 -> 95 | H14: =G14 -> 95 | K14: Cash
A15: Deferred tax assets (net) | B15: 1058 | C15: 0 | D15: 0 | E15: 0 | F15: 0 | G15: =F15 -> 0 | H15: =G15 -> 0
A16: Other non-current assets | B16: 431 | C16: 275 | D16: 290 | E16: 569 | F16: 591 | G16: =F16 -> 591 | H16: =G16 -> 591
A17: Income tax assets | B17: 885 | C17: 884 | D17: 145 | E17: 145 | F17: 140 | G17: =F17 -> 140 | H17: =G17 -> 140 | L17: Most assets are in plant and machinery → shows a core operating business, not idle assets
A18: Total non-current assets | B18: =B8+B9+B10+B13+B14+B15+B16+B17 -> 21159 | C18: =C8+C9+C10+C12+C13+C14+C15+C16+C17 -> 20688 | D18: =D8+D9+D10+D12+D13+D14+D15+D16+D17 -> 20663 | E18: =E8+E9+E10+E12+E13+E14+E15+E16+E17 -> 21270 | F18: =F8+F9+F10+F12+F13+F14+F15+F16+F17 -> 22864 | G18: =G8+G9+G10+G12+G13+G14+G15+G16+G17 -> 23036.996 | H18: =H8+H9+H10+H12+H13+H14+H15+H16+H17 -> 23122.794 | L18: Cash and investments fluctuate → active cash management.
L19: Inventory levels look controlled → no sign of overstocking.
A20: current assets | L20: Equity is the main funding source → strong financial base.
A21: Inventories | B21: 1425 | C21: 1953 | D21: 1862 | E21: 1926 | F21: 1889 | G21: =G22*'P&L '!G10 -> 245.89193 | H21: =H22*'P&L '!H10 -> 3920.0046 | L21: Debt is present but reasonable → leverage is under control.
A22: % of COGS | B22: =B21/'P&L '!B10 -> 0.3012685 | C22: =C21/'P&L '!C10 -> 0.33436055 | D22: =D21/'P&L '!D10 -> 0.24384494 | E22: =E21/'P&L '!E10 -> 0.31049492 | F22: =F21/'P&L '!F10 -> 0.28022549 | G22: =AVERAGE(B22:F22) -> 0.29403888 | H22: =AVERAGE(C22:G22) -> 0.29259296 | L22: Current liabilities rise with operations → normal business growth pattern.
A23: Financial Assets | L23: Ongoing increase in fixed assets → company is expanding.
A24: Investments | B24: 12957 | C24: 15052 | D24: 9850 | E24: 9874 | F24: 9149 | G24: =F24 -> 9149 | H24: =G24 -> 9149 | I24: based on news | L24: Overall: Financial position looks stable, risk is moderate, and the structure supports future growth.
A25: Trade receivables | B25: 406 | C25: 716 | D25: 380 | E25: 155 | F25: 117 | G25: =G26*'P&L '!G8 -> 49.746529 | H25: =H26*'P&L '!H8 -> 726.38297
A26: % of Net Revenue | B26: =B25/'P&L '!B8 -> 0.018395179 | C26: =C25/'P&L '!C8 -> 0.024869746 | D26: =D25/'P&L '!D8 -> 0.011421015 | E26: =E25/'P&L '!E8 -> 0.0055195499 | F26: =F25/'P&L '!F8 -> 0.0035410551 | G26: =AVERAGE(B26:F26) -> 0.012749309 | H26: =AVERAGE(C26:G26) -> 0.011620135
A27: Cash and cash equivalents | B27: 313 | C27: 1592 | D27: 59 | E27: 53 | F27: 96 | G27: ='Cash flow'!G63 -> 96 | H27: ='Cash flow'!H63 -> 96
A28: Other Bank balances | B28: 9063 | C28: 4171 | D28: 1353 | E28: 122 | F28: 81 | G28: =F28 -> 81 | H28: =G28 -> 81
A29: Loans | B29: 2 | C29: 2 | D29: 3 | E29: 1 | F29: 1 | G29: =F29 -> 1 | H29: =G29 -> 1 | I29: based on news
A30: Others | B30: 53 | C30: 33 | D30: 89 | E30: 59 | F30: 41 | G30: =F30 -> 41 | H30: =G30 -> 41
A31: Income tax assets | B31: 0 | C31: 0 | D31: 872 | E31: 0 | F31: 1 | G31: =F31 -> 1 | H31: =G31 -> 1
A32: Other current assets | B32: 349 | C32: 463 | D32: 336 | E32: 435 | F32: 251 | G32: =F32 -> 251 | H32: =G32 -> 251
A33: Total current assets | B33: =B21+B24+B25+B27+B28+B29+B30+B32 -> 24568 | C33: =C21+C24+C25+C27+C28+C29+C30+C32 -> 23982 | D33: =D21+D24+D25+D27+D28+D29+D30+D31+D32 -> 14804 | E33: =E21+E24+E25+E27+E28+E29+E30+E31+E32 -> 12625 | F33: =F21+F24+F25+F27+F28+F29+F30+F31+F32 -> 11626 | G33: =G21+G24+G25+G27+G28+G29+G30+G31+G32 -> 9915.6385 | H33: =H21+H24+H25+H27+H28+H29+H30+H31+H32 -> 14266.388
A34: TOTAL | B34: =B18+B33 -> 45727 | C34: =C18+C33 -> 44670 | D34: =D18+D33 -> 35467 | E34: =E18+E33 -> 33895 | F34: =F18+F33 -> 34490 | G34: =G18+G33 -> 32952.634 | H34: =H18+H33 -> 37389.181
A36: EQUITY AND LIABILITES
A37: equity
A38: Equity share capital | B38: 845 | C38: 845 | D38: 845 | E38: 845 | F38: 845 | G38: =F38 -> 845 | H38: =G38 -> 845 | I38: based on news
A39: Other equity | B39: 31468 | C39: 33436 | D39: 12087 | E39: 14350 | F39: 12481 | G39: =F39+'P&L '!G34-'Ratio Analysis'!H8 -> 10974.065 | H39: =G39+'P&L '!H34-'Ratio Analysis'!I8 -> 31506.909 | I39: Last year other equity-current year profit-current year dividend
A40: Total equity | B40: =B38+B39 -> 32313 | C40: =C39+C38 -> 34281 | D40: =D38+D39 -> 12932 | E40: =E38+E39 -> 15195 | F40: =F38+F39 -> 13326 | G40: =G38+G39 -> 11819.065 | H40: =H38+H39 -> 32351.909
A42: Liabilities
A43: non-current liabilities
A44: Financial liabilities
...

Sheet Cash flow
A1: Hindustan Zinc | B1: 44286 | C1: 44651 | D1: 45016 | E1: 45382 | F1: 45747 | G1: 46112 | H1: 46477
A2: Cash Flow Statement | B2: Y | C2: Y | D2: Y | E2: Y | F2: Y | G2: Y | H2: Y
A3: (in INR Crores) | B3: Act | C3: Act | D3: Act | E3: Act | F3: Act | G3: Est | H3: Est
A5: Cash Flow From Operating Activities
A6: Net profit before tax | B6: 10574 | C6: 14100 | D6: 15288 | E6: 10307 | F6: 13553 | G6: ='P&L '!G29 -> -1915.6506 | H6: ='P&L '!H29 -> 26785.505 | J6: Operating Cash Flow
A7: Adjustments to reconcile profit to net cash | J7: Positive in most years → core business generates real cash.
A8: Depreciation and amortization expense | B8: 2531 | C8: 2917 | D8: 3264 | E8: 3468 | F8: 3640 | G8: ='P&L '!G23 -> 4103.6177 | H8: ='P&L '!H23 -> 4512.8743 | J8: Moves in line with profits → earnings quality looks reliable.
A9: Exceptional item | B9: 0 | C9: 0 | D9: 0 | E9: 0 | F9: 56 | G9: ='P&L '!G25 -> -1040.5552 | H9: ='P&L '!H25 -> 27704.822 | J9: Some fluctuations → working capital changes affecting cash timing.
A10: Interest expense | B10: 386 | C10: 290 | D10: 333 | E10: 955 | F10: 1095 | G10: ='P&L '!G26 -> 0 | H10: ='P&L '!H26 -> 0
A11: Interest income | B11: -941 | C11: -838 | D11: -1154 | E11: -761 | F11: -705 | G11: ='P&L '!G27 -> 875.09541 | H11: ='P&L '!H27 -> 919.31697
A12: Amortization of deferred revenue | B12: -120 | C12: -135 | D12: -157 | E12: -179 | F12: -176 | G12: ='P&L '!G29 -> -1915.6506 | H12: ='P&L '!H29 -> 26785.505
A13: Allowance for impairment loss on financial assets | B13: 0 | C13: 0 | D13: 0 | E13: 0 | F13: 0 | G13: ='P&L '!G30 -> 0 | H13: ='P&L '!H30 -> 0
A14: Provision for doubtful debts/ advance | B14: 0 | C14: 0 | D14: 28 | E14: 0 | F14: 0 | G14: ='P&L '!G31 -> -408.71608 | H14: ='P&L '!H31 -> 6194.0926
A15: Net Loss on investments measured at FVTPL | B15: 0 | C15: 28 | D15: 16 | E15: -64 | F15: 0 | G15: ='P&L '!G32 -> 0.21335628 | H15: ='P&L '!H32 -> 0.23124793
A16: Net (Gain)/Loss on foreign exchange | B16: 0 | C16: 0 | D16: 0 | E16: -13 | F16: 43 | G16: ='P&L '!G33 -> 0 | H16: ='P&L '!H33 -> 0
A17: Net gain on investments measured at FVTPL | B17: -400 | C17: 0 | D17: 0 | E17: 0 | F17: 28 | G17: ='P&L '!G34 -> -1506.9346 | H17: ='P&L '!H34 -> 20591.413
A18: Net (Gain)/Loss on sale of Property, Plant and Equipment | B18: -42 | C18: -11 | D18: 9 | E18: 20 | F18: 9 | G18: ='P&L '!G35 -> 0 | H18: ='P&L '!H35 -> 0
A19: Net (Gain) on sale of financial asset investments | B19: -304 | C19: -205 | D19: -32 | E19: -37 | F19: -63 | G19: ='P&L '!G36 -> 0 | H19: ='P&L '!H36 -> 0
A20: Charge pertaining to Amnesty Scheme | B20: 0 | C20: 134 | D20: 0 | E20: 0 | F20: 0 | G20: ='P&L '!G37 -> 0 | H20: ='P&L '!H37 -> 0
A21: Transfer of CSR Assets | B21: 0 | C21: 0 | D21: 117 | E21: 0 | F21: 0 | G21: ='P&L '!G38 -> 357.56552 | H21: ='P&L '!H38 -> 5892.9968
A22: operating profit before working capital changes | B22: =B6+B8+B10+B11+B12+B17+B18+B19 -> 11684 | C22: =C6+C8+C10+C11+C12+C17+C18+C19 -> 16118 | D22: =D6+D8+D10+D11+D12+D17+D18+D19 -> 17551 | E22: =E6+E8+E10+E11+E12+E17+E18+E19 -> 13773 | F22: =F6+F8+F10+F11+F12+F17+F18+F19 -> 17381 | G22: =G6+G8+G10+G11+G12+G17+G18+G19 -> -359.52275 | H22: =H6+H8+H10+H11+H12+H17+H18+H19 -> 79594.615
A24: changes in assets and liabilities
A25: Increase)/Decrease in Inventories | B25: 411 | C25: -528 | D25: 91 | E25: -64 | F25: 37 | G25: ='Balance sheet'!F21-'Balance sheet'!G21 -> 1643.1081 | H25: ='Balance sheet'!G21-'Balance sheet'!H21 -> -3674.1127
A26: (Increase)/Decrease in Trade receivables | B26: -26 | C26: -310 | D26: 336 | E26: 225 | F26: 38 | G26: ='Balance sheet'!F25-'Balance sheet'!G25 -> 67.253471 | H26: ='Balance sheet'!G25-'Balance sheet'!H25 -> -676.63644
A27: (Increase)/Decrease in Other current assets | B27: -52 | C27: -94 | D27: 42 | E27: -66 | F27: 212 | G27: ='Balance sheet'!F28-'Balance sheet'!G28+'Balance sheet'!F30-'Balance sheet'!G30+'Balance sheet'!F31-'Balance sheet'!G31+'Balance sheet'!F32-'Balance sheet'!G32 -> 0 | H27: ='Balance sheet'!G28-'Balance sheet'!H28+'Balance sheet'!G30-'Balance sheet'!H30+'Balance sheet'!G31-'Balance sheet'!H31+'Balance sheet'!G32-'Balance sheet'!H32 -> 0
A28: (Increase)/Decrease in Other non current assets | B28: 12 | C28: 4 | D28: -57 | E28: -3 | F28: -91 | G28: ='Balance sheet'!F10-'Balance sheet'!G10+'Balance sheet'!F14-'Balance sheet'!G14+'Balance sheet'!F15-'Balance sheet'!G15+'Balance sheet'!G16-'Balance sheet'!F16+'Balance sheet'!F17-'Balance sheet'!G17 -> 0 | H28: ='Balance sheet'!G10-'Balance sheet'!H10+'Balance sheet'!G14-'Balance sheet'!H14+'Balance sheet'!G15-'Balance sheet'!H15+'Balance sheet'!H16-'Balance sheet'!G16+'Balance sheet'!G17-'Balance sheet'!H17 -> 0
A29: (Increase/(Decrease) in Trade payables | B29: 58 | C29: 773 | D29: 77 | E29: 109 | F29: 269 | G29: ='Balance sheet'!G59-'Balance sheet'!F59+'Balance sheet'!G61-'Balance sheet'!F61 -> -1933.6516 | H29: ='Balance sheet'!H59-'Balance sheet'!G59+'Balance sheet'!H61-'Balance sheet'!G61 -> 4047.196
A30: (Increase/(Decrease) in Other current liabilities | B30: 235 | C30: -1043 | D30: 68 | E30: 1206 | F30: -400 | G30: ='Balance sheet'!G60-'Balance sheet'!F60+'Balance sheet'!G62-'Balance sheet'!F62 -> -0.0037777258 | H30: ='Balance sheet'!H60-'Balance sheet'!G60+'Balance sheet'!H62-'Balance sheet'!G62 -> -0.0047839203
A31: (Increase/(Decrease) in non current liabilities | B31: 0 | C31: 0 | D31: 0 | E31: 0 | F31: 0 | G31: ='Balance sheet'!G61-'Balance sheet'!F61+'Balance sheet'!G63-'Balance sheet'!F63 -> 56.680782 | H31: ='Balance sheet'!H61-'Balance sheet'!G61+'Balance sheet'!H63-'Balance sheet'!G63 -> 127.10776
A32: cash flows from operations | B32: =B22+B25+B26+B27+B28+B29+B30+B31 -> 12322 | C32: =C22+C25+C26+C27+C28+C29+C30+C31 -> 14920 | D32: =D22+D25+D26+D27+D28+D29+D30+D31 -> 18108 | E32: =E22+E25+E26+E27+E28+E29+E30+E31 -> 15180 | F32: =F22+F25+F26+F27+F28+F29+F30+F31 -> 17446 | G32: =G22+G25+G26+G27+G28+G29+G30+G31 -> -526.13586 | H32: =H22+H25+H26+H27+H28+H29+H30+H31 -> 79418.164
A33: Income taxes paid during the year | B33: 1755 | C33: -2391 | D33: -3140 | E33: -1757 | F33: -3385 | G33: ='P&L '!G31 -> -408.71608 | H33: ='P&L '!H31 -> 6194.0926
A34: net cash flows from operating activities | B34: =B32-B33 -> 10567 | C34: =C32-C33 -> 17311 | D34: =D32-D33 -> 21248 | E34: =E32-E33 -> 16937 | F34: =F32-F33 -> 20831 | G34: =G32-G33 -> -117.41977 | H34: =H32-H33 -> 73224.072
A36: Cash Flow From Investing Activities | J36: Investing Cash Flow
A37: Purchases of Property, Plant and Equipment | B37: -2481 | C37: -2998 | D37: -3561 | E37: -3866 | F37: -4006 | G37: ='Capex model'!F6-'Capex model'!G6 -> -4276.6137 | H37: ='Capex model'!G6-'Capex model'!H6 -> -4598.6721 | J37: Mostly negative → company is investing in assets and expansion.
A38: Interest received | B38: 1507 | C38: 936 | D38: 1438 | E38: 538 | F38: 663 | G38: ='Capex model'!F7-'Capex model'!G7 -> -0.00096527018 | H38: ='Capex model'!G7-'Capex model'!H7 -> 0.0015875431 | J38: Large outflows for plant and equipment → growth strategy in action.
A39: Deposits made during the year | B39: -9952 | C39: -5500 | D39: -1500 | E39: 4 | F39: -984 | G39: ='Capex model'!F8-'Capex model'!G8 -> -4103.6177 | H39: ='Capex model'!G8-'Capex model'!H8 -> -4512.8743 | J39: Occasional inflows from asset sales → asset optimization.
A40: Deposits matured during the year | B40: 1244 | C40: 10227 | D40: 5500 | E40: -92 | F40: 1022 | G40: ='Capex model'!F9-'Capex model'!G9 -> -172.99602 | H40: ='Capex model'!G9-'Capex model'!H9 -> -85.797722
A41: Purchase of Non current investments | B41: 0 | C41: 0 | D41: -105 | E41: -306 | F41: -230 | G41: ='Capex model'!F10-'Capex model'!G10 -> 0 | H41: ='Capex model'!G10-'Capex model'!H10 -> 0
A42: Purchase of current investments | B42: -41385 | C42: -46753 | D42: -43187 | E42: -23242 | F42: -23902 | G42: ='Capex model'!F11-'Capex model'!G11 -> 0 | H42: ='Capex model'!G11-'Capex model'!H11 -> 0
A43: Proceeds from sale of current investments | B43: 48578 | C43: 44904 | D43: 47958 | E43: 23507 | F43: 24724 | G43: ='Capex model'!F12-'Capex model'!G12 -> 0 | H43: ='Capex model'!G12-'Capex model'!H12 -> 0
...

Sheet Common Size  P&L
A3: Hindustan Zinc | B3: 44286 | C3: 44651 | D3: 45016 | E3: 45382 | F3: 45747 | G3: 46112 | H3: 46477
A4: Common Size P&L | B4: Y | C4: Y | D4: Y | E4: Y | F4: Y | G4: Y | H4: Y
A5: (in INR Crores) | B5: Act | C5: Act | D5: Act | E5: Act | F5: Act | G5: Est | H5: Est
A7: Revenue from operations | B7: ='P&L '!B6/'P&L '!$B$8 -> 1 | C7: ='P&L '!C6/'P&L '!$C$8 -> 1 | D7: ='P&L '!D6/'P&L '!$D$8 -> 1 | E7: ='P&L '!E6/'P&L '!$E$8 -> 1 | F7: ='P&L '!F6/'P&L '!$F$8 -> 1 | G7: ='P&L '!G6/'P&L '!$G$8 -> 1 | H7: ='P&L '!H6/'P&L '!$H$8 -> 1 | J7: Cost structure is stable with consistent COGS percentage, showing operational control.
A8: Excise duty | B8: ='P&L '!B7/'P&L '!$B$8 -> 0 | C8: ='P&L '!C7/'P&L '!$C$8 -> 0 | D8: ='P&L '!D7/'P&L '!$D$8 -> 0 | E8: ='P&L '!E7/'P&L '!$E$8 -> 0 | F8: ='P&L '!F7/'P&L '!$F$8 -> 0 | G8: ='P&L '!G7/'P&L '!$G$8 -> 0 | H8: ='P&L '!H7/'P&L '!$H$8 -> 0 | J8: Margins remain strong overall, though they fluctuate with revenue cycles.
A9: Net Revenue | B9: ='P&L '!B8/'P&L '!$B$8 -> 1 | C9: ='P&L '!C8/'P&L '!$C$8 -> 1 | D9: ='P&L '!D8/'P&L '!$D$8 -> 1 | E9: ='P&L '!E8/'P&L '!$E$8 -> 1 | F9: ='P&L '!F8/'P&L '!$F$8 -> 1 | G9: ='P&L '!G8/'P&L '!$G$8 -> 1 | H9: ='P&L '!H8/'P&L '!$H$8 -> 1 | J9: Operating expenses are low and stable, indicating efficient cost management.
J10: Profitability mainly depends on sales performance and commodity price movements.
A11: Cost of Goods Sold | B11: ='P&L '!B10/'P&L '!$B$8 -> 0.21430837 | C11: ='P&L '!C10/'P&L '!$C$8 -> 0.20288295 | D11: ='P&L '!D10/'P&L '!$D$8 -> 0.22950228 | E11: ='P&L '!E10/'P&L '!$E$8 -> 0.22088883 | F11: ='P&L '!F10/'P&L '!$F$8 -> 0.20401925 | G11: ='P&L '!G10/'P&L '!$G$8 -> 0.21432033 | H11: ='P&L '!H10/'P&L '!$H$8 -> 0.21432273
A12: Power and fuel | B12: ='P&L '!B11/'P&L '!$B$8 -> 0.078474016 | C12: ='P&L '!C11/'P&L '!$C$8 -> 0.085168461 | D12: ='P&L '!D11/'P&L '!$D$8 -> 0.11153522 | E12: ='P&L '!E11/'P&L '!$E$8 -> 0.10123923 | F12: ='P&L '!F11/'P&L '!$F$8 -> 0.081777186 | G12: ='P&L '!G11/'P&L '!$G$8 -> 0.091638823 | H12: ='P&L '!H11/'P&L '!$H$8 -> 0.094271785
A13: Mining Royalty | B13: ='P&L '!B12/'P&L '!$B$8 -> 0.12500566 | C13: ='P&L '!C12/'P&L '!$C$8 -> 0.12737061 | D13: ='P&L '!D12/'P&L '!$D$8 -> 0.12226497 | E13: ='P&L '!E12/'P&L '!$E$8 -> 0.12524037 | F13: ='P&L '!F12/'P&L '!$F$8 -> 0.12417905 | G13: ='P&L '!G12/'P&L '!$G$8 -> 0.12481213 | H13: ='P&L '!H12/'P&L '!$H$8 -> 0.12477343
A14: Changes in inventories of finished goods | B14: ='P&L '!B13/'P&L '!$B$8 -> 0.010828689 | C14: ='P&L '!C13/'P&L '!$C$8 -> -0.0096561306 | D14: ='P&L '!D13/'P&L '!$D$8 -> -0.0042979082 | E14: ='P&L '!E13/'P&L '!$E$8 -> -0.0055907699 | F14: ='P&L '!F13/'P&L '!$F$8 -> -0.0019369874 | G14: ='P&L '!G13/'P&L '!$G$8 -> -0.0021306214 | H14: ='P&L '!H13/'P&L '!$H$8 -> -0.0047224835
A15: Gross Profit | B15: ='P&L '!B14/'P&L '!$B$8 -> 1 | C15: ='P&L '!C14/'P&L '!$C$8 -> 0.79711705 | D15: ='P&L '!D14/'P&L '!$D$8 -> 0.77049772 | E15: ='P&L '!E14/'P&L '!$E$8 -> 0.77911117 | F15: ='P&L '!F14/'P&L '!$F$8 -> 0.79598075 | G15: ='P&L '!G14/'P&L '!$G$8 -> 0.78567967 | H15: ='P&L '!H14/'P&L '!$H$8 -> 0.78567727
A17: Selling & General Adm Expenses | B17: ='P&L '!B16/'P&L '!$B$8 -> 0 | C17: ='P&L '!C16/'P&L '!$C$8 -> 0 | D17: ='P&L '!D16/'P&L '!$D$8 -> 0 | E17: ='P&L '!E16/'P&L '!$E$8 -> 0 | F17: ='P&L '!F16/'P&L '!$F$8 -> 0 | G17: ='P&L '!G16/'P&L '!$G$8 -> 0 | H17: ='P&L '!H16/'P&L '!$H$8 -> 0
A18: Employee benefits expense | B18: ='P&L '!B17/'P&L '!$B$8 -> 0.034434326 | C18: ='P&L '!C17/'P&L '!$C$8 -> 0.024939215 | D18: ='P&L '!D17/'P&L '!$D$8 -> 0.02539673 | E18: ='P&L '!E17/'P&L '!$E$8 -> 0.029485079 | F18: ='P&L '!F17/'P&L '!$F$8 -> 0.026815169 | G18: ='P&L '!G17/'P&L '!$G$8 -> 0.028214104 | H18: ='P&L '!H17/'P&L '!$H$8 -> 0.026970059
A19: Other expenses | B19: ='P&L '!B18/'P&L '!$B$8 -> 0.2477006 | C19: ='P&L '!C18/'P&L '!$C$8 -> 0.23119139 | D19: ='P&L '!D18/'P&L '!$D$8 -> 0.24377855 | E19: ='P&L '!E18/'P&L '!$E$8 -> 0.29360444 | F19: ='P&L '!F18/'P&L '!$F$8 -> 0.2744469 | G19: ='P&L '!G18/'P&L '!$G$8 -> 0.25814438 | H19: ='P&L '!H18/'P&L '!$H$8 -> 0.26023313
A20: EBITDA | B20: ='P&L '!B19/'P&L '!$B$8 -> 0.71786507 | C20: ='P&L '!C19/'P&L '!$C$8 -> 0.54098645 | D20: ='P&L '!D19/'P&L '!$D$8 -> 0.50132243 | E20: ='P&L '!E19/'P&L '!$E$8 -> 0.45602165 | F20: ='P&L '!F19/'P&L '!$F$8 -> 0.49471868 | G20: ='P&L '!G19/'P&L '!$G$8 -> 0.49932118 | H20: ='P&L '!H19/'P&L '!$H$8 -> 0.49847408
A22: Other income | B22: ='P&L '!B21/'P&L '!$B$8 -> 0.08241584 | C22: ='P&L '!C21/'P&L '!$C$8 -> 0.042236888 | D22: ='P&L '!D21/'P&L '!$D$8 -> 0.041446261 | E22: ='P&L '!E21/'P&L '!$E$8 -> 0.038245139 | F22: ='P&L '!F21/'P&L '!$F$8 -> 0.029750916 | G22: ='P&L '!G21/'P&L '!$G$8 -> 0.28569699 | H22: ='P&L '!H21/'P&L '!$H$8 -> 0.016920693
A23: Depreciation and amortization expense | B23: ='P&L '!B23/'P&L '!$B$8 -> 0.11467537 | C23: ='P&L '!C23/'P&L '!$C$8 -> 0.1012157 | D23: ='P&L '!D23/'P&L '!$D$8 -> 0.098100505 | E23: ='P&L '!E23/'P&L '!$E$8 -> 0.12349548 | F23: ='P&L '!F23/'P&L '!$F$8 -> 0.11016616 | G23: ='P&L '!G22/'P&L '!$G$8 -> 2.8649919e-05 | H23: ='P&L '!H22/'P&L '!$H$8 -> 1.6968204e-06
A24: EBIT | B24: ='P&L '!B25/'P&L '!$B$8 -> 0.68560555 | C24: ='P&L '!C25/'P&L '!$C$8 -> 0.48200764 | D24: ='P&L '!D25/'P&L '!$D$8 -> 0.44466819 | E24: ='P&L '!E25/'P&L '!$E$8 -> 0.37077131 | F24: ='P&L '!F25/'P&L '!$F$8 -> 0.41430344 | G24: ='P&L '!G23/'P&L '!$G$8 -> 1.0516973 | H24: ='P&L '!H23/'P&L '!$H$8 -> 0.072193611
A26: Finance costs | B26: ='P&L '!B27/'P&L '!$B$8 -> 0.017489013 | C26: ='P&L '!C27/'P&L '!$C$8 -> 0.010072942 | D26: ='P&L '!D27/'P&L '!$D$8 -> 0.010008415 | E26: ='P&L '!E27/'P&L '!$E$8 -> 0.034007549 | F26: ='P&L '!F27/'P&L '!$F$8 -> 0.033140643 | G26: ='P&L '!G25/'P&L '!$G$8 -> -0.26667911 | H26: ='P&L '!H25/'P&L '!$H$8 -> 0.44320116
A27: PBT | B27: ='P&L '!B29/'P&L '!$B$8 -> 0.66811653 | C27: ='P&L '!C29/'P&L '!$C$8 -> 0.4719347 | D27: ='P&L '!D29/'P&L '!$D$8 -> 0.43465977 | E27: ='P&L '!E29/'P&L '!$E$8 -> 0.33676376 | F27: ='P&L '!F29/'P&L '!$F$8 -> 0.3811628 | G27: ='P&L '!G26/'P&L '!$G$8 -> 0 | H27: ='P&L '!H26/'P&L '!$H$8 -> 0
A29: Current tax | B29: ='P&L '!B31/'P&L '!$B$8 -> 0.082778306 | C29: ='P&L '!C31/'P&L '!$C$8 -> 0.084925321 | D29: ='P&L '!D31/'P&L '!$D$8 -> 0.10311974 | E29: ='P&L '!E31/'P&L '!$E$8 -> 0.090769888 | F29: ='P&L '!F31/'P&L '!$F$8 -> 0.09763627 | G29: ='P&L '!G28/'P&L '!$G$8 -> 2.0449911e-05 | H29: ='P&L '!H28/'P&L '!$H$8 -> 1.340982e-06
A30: Deferred tax | B30: ='P&L '!B33/'P&L '!$B$8 -> 0.034751484 | C30: ='P&L '!C33/'P&L '!$C$8 -> 0.070371657 | D30: ='P&L '!D33/'P&L '!$D$8 -> 0.040454436 | E30: ='P&L '!E33/'P&L '!$E$8 -> -3.5609999e-05 | F30: ='P&L '!F33/'P&L '!$F$8 -> -0.00078690112 | G30: ='P&L '!G29/'P&L '!$G$8 -> -0.49095329 | H30: ='P&L '!H29/'P&L '!$H$8 -> 0.42849461
A31: PAT | B31: ='P&L '!B34/'P&L '!$B$8 -> 0.55058674 | C31: ='P&L '!C34/'P&L '!$C$8 -> 0.31663772 | D31: ='P&L '!D34/'P&L '!$D$8 -> 0.2910856 | E31: ='P&L '!E34/'P&L '!$E$8 -> 0.24602949 | F31: ='P&L '!F34/'P&L '!$F$8 -> 0.28431343 | G31: ='P&L '!G34/'P&L '!$F$8 -> -0.045608019 | H31: ='P&L '!H34/'P&L '!$F$8 -> 0.62320791

Sheet Common Size B&L
A3: Hindustan Zinc | B3: 44286 | C3: 44651 | D3: 45016 | E3: 45382 | F3: 45747 | G3: 46112 | H3: 46477
A4: Common Size B&L | B4: Y | C4: Y | D4: Y | E4: Y | F4: Y | G4: Y | H4: Y
A5: (in INR Crores) | B5: Act | C5: Act | D5: Act | E5: Act | F5: Act | G5: Est | H5: Est
A7: ASSETS | J7: Assets
A8: Non-current asset | J8: Fixed assets form the largest portion → business is asset-heavy and capital intensive.
A9: Property, plant and equipment | B9: ='Balance sheet'!B8/'Balance sheet'!$B$34 -> 0.35967809 | C9: ='Balance sheet'!C8/'Balance sheet'!$C$34 -> 0.38426237 | D9: ='Balance sheet'!D8/'Balance sheet'!$D$34 -> 0.49426227 | E9: ='Balance sheet'!E8/'Balance sheet'!$E$34 -> 0.53019619 | F9: ='Balance sheet'!F8/'Balance sheet'!$F$34 -> 0.53595245 | G9: ='Balance sheet'!G8/'Balance sheet'!$G$34 -> 0.56620651 | H9: ='Balance sheet'!H8/'Balance sheet'!$H$34 -> 0.50131597 | J9: Share of fixed assets increases over time → expansion and capacity growth.
A10: Capital work-in-progress | B10: ='Balance sheet'!B9/'Balance sheet'!$B$34 -> 0.04203206 | C10: ='Balance sheet'!C9/'Balance sheet'!$C$34 -> 0.046451757 | D10: ='Balance sheet'!D9/'Balance sheet'!$D$34 -> 0.063072715 | E10: ='Balance sheet'!E9/'Balance sheet'!$E$34 -> 0.050036879 | F10: ='Balance sheet'!F9/'Balance sheet'!$F$34 -> 0.075558133 | G10: ='Balance sheet'!G9/'Balance sheet'!$G$34 -> 0.079083207 | H10: ='Balance sheet'!H9/'Balance sheet'!$H$34 -> 0.069699306 | J10: Current assets fluctuate → working capital adjusts with operations.
A11: Intangible Assets | B11: ='Balance sheet'!B10/'Balance sheet'!$B$34 -> 0.0078946793 | C11: ='Balance sheet'!C10/'Balance sheet'!$C$34 -> 0.0051712559 | D11: ='Balance sheet'!D10/'Balance sheet'!$D$34 -> 0.0025939606 | E11: ='Balance sheet'!E10/'Balance sheet'!$E$34 -> 0.0053105178 | F11: ='Balance sheet'!F10/'Balance sheet'!$F$34 -> 0.0035662511 | G11: ='Balance sheet'!G10/'Balance sheet'!$G$34 -> 0.0037326302 | H11: ='Balance sheet'!H10/'Balance sheet'!$H$34 -> 0.0032897217 | J11: Cash proportion is relatively low → funds are mostly deployed, not idle.
A12: Financial assets
A13: Investments | B13: ='Balance sheet'!B12/'Balance sheet'!$B$34 -> 0 | C13: ='Balance sheet'!C12/'Balance sheet'!$C$34 -> 0 | D13: ='Balance sheet'!D12/'Balance sheet'!$D$34 -> 0.0072461725 | E13: ='Balance sheet'!E12/'Balance sheet'!$E$34 -> 0.017052663 | F13: ='Balance sheet'!F12/'Balance sheet'!$F$34 -> 0.023861989 | G13: ='Balance sheet'!G12/'Balance sheet'!$G$34 -> 0.024975241 | H13: ='Balance sheet'!H12/'Balance sheet'!$H$34 -> 0.022011715
A14: Loans | B14: ='Balance sheet'!B13/'Balance sheet'!$B$34 -> 0.00026242701 | C14: ='Balance sheet'!C13/'Balance sheet'!$C$34 -> 4.4772778e-05 | D14: ='Balance sheet'!D13/'Balance sheet'!$D$34 -> 0 | E14: ='Balance sheet'!E13/'Balance sheet'!$E$34 -> 0 | F14: ='Balance sheet'!F13/'Balance sheet'!$F$34 -> 2.8993911e-05 | G14: ='Balance sheet'!G13/'Balance sheet'!$G$34 -> 3.0346587e-05 | H14: ='Balance sheet'!H13/'Balance sheet'!$H$34 -> 2.6745705e-05
A15: Others | B15: ='Balance sheet'!B14/'Balance sheet'!$B$34 -> 0.00094036346 | C15: ='Balance sheet'!C14/'Balance sheet'!$C$34 -> 0.0012536378 | D15: ='Balance sheet'!D14/'Balance sheet'!$D$34 -> 0.0031578651 | E15: ='Balance sheet'!E14/'Balance sheet'!$E$34 -> 0.0038648768 | F15: ='Balance sheet'!F14/'Balance sheet'!$F$34 -> 0.0027544216 | G15: ='Balance sheet'!G14/'Balance sheet'!$G$34 -> 0.0028829258 | H15: ='Balance sheet'!H14/'Balance sheet'!$H$34 -> 0.0025408419
A16: Deferred tax assets (net) | B16: ='Balance sheet'!B15/'Balance sheet'!$B$34 -> 0.023137315 | C16: ='Balance sheet'!C15/'Balance sheet'!$C$34 -> 0 | D16: ='Balance sheet'!D15/'Balance sheet'!$D$34 -> 0 | E16: ='Balance sheet'!E15/'Balance sheet'!$E$34 -> 0 | F16: ='Balance sheet'!F15/'Balance sheet'!$F$34 -> 0 | G16: ='Balance sheet'!G15/'Balance sheet'!$G$34 -> 0 | H16: ='Balance sheet'!H15/'Balance sheet'!$H$34 -> 0
A17: Other non-current assets | B17: ='Balance sheet'!B16/'Balance sheet'!$B$34 -> 0.0094255035 | C17: ='Balance sheet'!C16/'Balance sheet'!$C$34 -> 0.006156257 | D17: ='Balance sheet'!D16/'Balance sheet'!$D$34 -> 0.0081766149 | E17: ='Balance sheet'!E16/'Balance sheet'!$E$34 -> 0.016787137 | F17: ='Balance sheet'!F16/'Balance sheet'!$F$34 -> 0.017135402 | G17: ='Balance sheet'!G16/'Balance sheet'!$G$34 -> 0.017934833 | H17: ='Balance sheet'!H16/'Balance sheet'!$H$34 -> 0.015806711
A18: Income tax assets | B18: ='Balance sheet'!B17/'Balance sheet'!$B$34 -> 0.019353992 | C18: ='Balance sheet'!C17/'Balance sheet'!$C$34 -> 0.019789568 | D18: ='Balance sheet'!D17/'Balance sheet'!$D$34 -> 0.0040883074 | E18: ='Balance sheet'!E17/'Balance sheet'!$E$34 -> 0.0042779171 | F18: ='Balance sheet'!F17/'Balance sheet'!$F$34 -> 0.0040591476 | G18: ='Balance sheet'!G17/'Balance sheet'!$G$34 -> 0.0042485222 | H18: ='Balance sheet'!H17/'Balance sheet'!$H$34 -> 0.0037443987
A19: Total non-current assets | B19: ='Balance sheet'!B18/'Balance sheet'!$B$34 -> 0.46272443 | C19: ='Balance sheet'!C18/'Balance sheet'!$B$34 -> 0.45242417 | D19: ='Balance sheet'!D18/'Balance sheet'!$B$34 -> 0.45187745 | E19: ='Balance sheet'!E18/'Balance sheet'!$B$34 -> 0.46515188 | F19: ='Balance sheet'!F18/'Balance sheet'!$B$34 -> 0.50001093 | G19: ='Balance sheet'!G18/'Balance sheet'!$G$34 -> 0.69909421 | H19: ='Balance sheet'!H18/'Balance sheet'!$G$34 -> 0.70169788
A21: current assets
A22: Inventories | B22: ='Balance sheet'!B21/'Balance sheet'!$B$34 -> 0.031163208 | C22: ='Balance sheet'!C21/'Balance sheet'!$C$34 -> 0.043720618 | D22: ='Balance sheet'!D21/'Balance sheet'!$D$34 -> 0.052499507 | E22: ='Balance sheet'!E21/'Balance sheet'!$E$34 -> 0.05682254 | F22: ='Balance sheet'!F21/'Balance sheet'!$F$34 -> 0.054769498 | G22: ='Balance sheet'!G21/'Balance sheet'!$G$34 -> 0.0074619809 | H22: ='Balance sheet'!H21/'Balance sheet'!$H$34 -> 0.10484328
A23: Financial Assets
A24: Investments | B24: ='Balance sheet'!B24/'Balance sheet'!$B$34 -> 0.28335557 | C24: ='Balance sheet'!C24/'Balance sheet'!$C$34 -> 0.33695993 | D24: ='Balance sheet'!D24/'Balance sheet'!$D$34 -> 0.27772295 | E24: ='Balance sheet'!E24/'Balance sheet'!$E$34 -> 0.2913114 | F24: ='Balance sheet'!F24/'Balance sheet'!$F$34 -> 0.26526529 | G24: ='Balance sheet'!G23/'Balance sheet'!$G$34 -> 0 | H24: ='Balance sheet'!H23/'Balance sheet'!$H$34 -> 0
A25: Trade receivables | B25: ='Balance sheet'!B25/'Balance sheet'!$B$34 -> 0.0088787806 | C25: ='Balance sheet'!C25/'Balance sheet'!$C$34 -> 0.016028655 | D25: ='Balance sheet'!D25/'Balance sheet'!$D$34 -> 0.010714185 | E25: ='Balance sheet'!E25/'Balance sheet'!$E$34 -> 0.0045729459 | F25: ='Balance sheet'!F25/'Balance sheet'!$F$34 -> 0.0033922876 | G25: ='Balance sheet'!G24/'Balance sheet'!$G$34 -> 0.27764093 | H25: ='Balance sheet'!H24/'Balance sheet'!$H$34 -> 0.24469645
A26: Cash and cash equivalents | B26: ='Balance sheet'!B27/'Balance sheet'!$B$34 -> 0.0068449712 | C26: ='Balance sheet'!C27/'Balance sheet'!$C$34 -> 0.035639131 | D26: ='Balance sheet'!D27/'Balance sheet'!$D$34 -> 0.0016635182 | E26: ='Balance sheet'!E27/'Balance sheet'!$E$34 -> 0.0015636525 | F26: ='Balance sheet'!F27/'Balance sheet'!$F$34 -> 0.0027834155 | G26: ='Balance sheet'!G25/'Balance sheet'!$G$34 -> 0.0015096374 | H26: ='Balance sheet'!H25/'Balance sheet'!$H$34 -> 0.019427624
A27: Other Bank balances | B27: ='Balance sheet'!B28/'Balance sheet'!$B$34 -> 0.198198 | C27: ='Balance sheet'!C28/'Balance sheet'!$C$34 -> 0.093373629 | D27: ='Balance sheet'!D28/'Balance sheet'!$D$34 -> 0.038148138 | E27: ='Balance sheet'!E28/'Balance sheet'!$E$34 -> 0.0035993509 | F27: ='Balance sheet'!F28/'Balance sheet'!$F$34 -> 0.0023485068 | G27: ='Balance sheet'!G26/'Balance sheet'!$G$34 -> 3.8689802e-07 | H27: ='Balance sheet'!H26/'Balance sheet'!$H$34 -> 3.107887e-07
A28: Loans | B28: ='Balance sheet'!B29/'Balance sheet'!$B$34 -> 4.3737835e-05 | C28: ='Balance sheet'!C29/'Balance sheet'!$C$34 -> 4.4772778e-05 | D28: ='Balance sheet'!D29/'Balance sheet'!$D$34 -> 8.4585671e-05 | E28: ='Balance sheet'!E29/'Balance sheet'!$E$34 -> 2.9502877e-05 | F28: ='Balance sheet'!F29/'Balance sheet'!$F$34 -> 2.8993911e-05 | G28: ='Balance sheet'!G27/'Balance sheet'!$G$34 -> 0.0029132724 | H28: ='Balance sheet'!H27/'Balance sheet'!$H$34 -> 0.0025675876
A29: Others | B29: ='Balance sheet'!B30/'Balance sheet'!$B$34 -> 0.0011590526 | C29: ='Balance sheet'!C30/'Balance sheet'!$C$34 -> 0.00073875084 | D29: ='Balance sheet'!D30/'Balance sheet'!$D$34 -> 0.0025093749 | E29: ='Balance sheet'!E30/'Balance sheet'!$E$34 -> 0.0017406697 | F29: ='Balance sheet'!F30/'Balance sheet'!$F$34 -> 0.0011887504 | G29: ='Balance sheet'!G28/'Balance sheet'!$G$34 -> 0.0024580736 | H29: ='Balance sheet'!H28/'Balance sheet'!$H$34 -> 0.0021664021
A30: Income tax assets | B30: ='Balance sheet'!B31/'Balance sheet'!$B$34 -> 0 | C30: ='Balance sheet'!C31/'Balance sheet'!$C$34 -> 0 | D30: ='Balance sheet'!D31/'Balance sheet'!$D$34 -> 0.024586235 | E30: ='Balance sheet'!E31/'Balance sheet'!$E$34 -> 0 | F30: ='Balance sheet'!F31/'Balance sheet'!$F$34 -> 2.8993911e-05 | G30: ='Balance sheet'!G29/'Balance sheet'!$G$34 -> 3.0346587e-05 | H30: ='Balance sheet'!H29/'Balance sheet'!$H$34 -> 2.6745705e-05
A31: Other current assets | B31: ='Balance sheet'!B32/'Balance sheet'!$B$34 -> 0.0076322523 | C31: ='Balance sheet'!C32/'Balance sheet'!$C$34 -> 0.010364898 | D31: ='Balance sheet'!D32/'Balance sheet'!$D$34 -> 0.0094735952 | E31: ='Balance sheet'!E32/'Balance sheet'!$E$34 -> 0.012833751 | F31: ='Balance sheet'!F32/'Balance sheet'!$F$34 -> 0.0072774717 | G31: ='Balance sheet'!G30/'Balance sheet'!$G$34 -> 0.0012442101 | H31: ='Balance sheet'!H30/'Balance sheet'!$H$34 -> 0.0010965739
A32: Total current assets | B32: ='Balance sheet'!B33/'Balance sheet'!$B$34 -> 0.53727557 | C32: ='Balance sheet'!C33/'Balance sheet'!$C$34 -> 0.53687038 | D32: ='Balance sheet'!D33/'Balance sheet'!$D$34 -> 0.41740209 | E32: ='Balance sheet'!E33/'Balance sheet'!$E$34 -> 0.37247382 | F32: ='Balance sheet'!F33/'Balance sheet'!$F$34 -> 0.33708321 | G32: ='Balance sheet'!G31/'Balance sheet'!$G$34 -> 3.0346587e-05 | H32: ='Balance sheet'!H31/'Balance sheet'!$H$34 -> 2.6745705e-05
A33: TOTAL | B33: ='Balance sheet'!B34/'Balance sheet'!$B$34 -> 1 | C33: ='Balance sheet'!C34/'Balance sheet'!$C$34 -> 1 | D33: ='Balance sheet'!D34/'Balance sheet'!$D$34 -> 1 | E33: ='Balance sheet'!E34/'Balance sheet'!$E$34 -> 1 | F33: ='Balance sheet'!F34/'Balance sheet'!$F$34 -> 1 | G33: ='Balance sheet'!G32/'Balance sheet'!$G$34 -> 0.0076169934 | H33: ='Balance sheet'!H32/'Balance sheet'!$H$34 -> 0.0067131719
A35: EQUITY AND LIABILITES | J35: Liabilities & Equity
A36: equity | J36: Equity contributes a major share → strong financial foundation.
A37: Equity share capital | B37: ='Balance sheet'!B38/'Balance sheet'!$B$34 -> 0.018479235 | C37: ='Balance sheet'!C38/'Balance sheet'!$C$34 -> 0.018916499 | D37: ='Balance sheet'!D38/'Balance sheet'!$D$34 -> 0.023824964 | E37: ='Balance sheet'!E38/'Balance sheet'!$E$34 -> 0.024929931 | F37: ='Balance sheet'!F38/'Balance sheet'!$F$34 -> 0.024499855 | G37: ='Balance sheet'!G36/'Balance sheet'!$G$34 -> 0 | H37: ='Balance sheet'!H36/'Balance sheet'!$H$34 -> 0 | J37: Debt portion is moderate → leverage is controlled
A38: Other equity | B38: ='Balance sheet'!B39/'Balance sheet'!$B$34 -> 0.6881711 | C38: ='Balance sheet'!C39/'Balance sheet'!$C$34 -> 0.74851131 | D38: ='Balance sheet'!D39/'Balance sheet'!$D$34 -> 0.34079567 | E38: ='Balance sheet'!E39/'Balance sheet'!$E$34 -> 0.42336628 | F38: ='Balance sheet'!F39/'Balance sheet'!$F$34 -> 0.36187301 | G38: ='Balance sheet'!G37/'Balance sheet'!$G$34 -> 0 | H38: ='Balance sheet'!H37/'Balance sheet'!$H$34 -> 0 | J38: Current liabilities move with business activity → normal operating cycle effect.
A39: Total equity | B39: ='Balance sheet'!B40/'Balance sheet'!$B$34 -> 0.70665034 | C39: ='Balance sheet'!C40/'Balance sheet'!$C$34 -> 0.7674278 | D39: ='Balance sheet'!D40/'Balance sheet'!$D$34 -> 0.36462063 | E39: ='Balance sheet'!E40/'Balance sheet'!$E$34 -> 0.44829621 | F39: ='Balance sheet'!F40/'Balance sheet'!$F$34 -> 0.38637286 | G39: ='Balance sheet'!G38/'Balance sheet'!$G$34 -> 0.025642866 | H39: ='Balance sheet'!H38/'Balance sheet'!$H$34 -> 0.02260012 | J39: No sharp spike in borrowings → disciplined financing approach.
A41: Liabilities
A42: non-current liabilities
A43: Financial liabilities
A44: Borrowings | B44: ='Balance sheet'!B45/'Balance sheet'!$B$34 -> 0.094298773 | C44: ='Balance sheet'!C45/'Balance sheet'!$C$34 -> 0.047257667 | D44: ='Balance sheet'!D45/'Balance sheet'!$D$34 -> 0.042292836 | E44: ='Balance sheet'!E45/'Balance sheet'!$E$34 -> 0.12526921 | F44: ='Balance sheet'!F45/'Balance sheet'!$F$34 -> 0.17367353 | G44: ='Balance sheet'!G43/'Balance sheet'!$G$34 -> 0 | H44: ='Balance sheet'!H43/'Balance sheet'!$H$34 -> 0
A45: Lease Liabilities | B45: ='Balance sheet'!B46/'Balance sheet'!$B$34 -> 0 | C45: ='Balance sheet'!C46/'Balance sheet'!$C$34 -> 0.00013431833 | D45: ='Balance sheet'!D46/'Balance sheet'!$D$34 -> 0.00053570925 | E45: ='Balance sheet'!E46/'Balance sheet'!$E$34 -> 0.005251512 | F45: ='Balance sheet'!F46/'Balance sheet'!$F$34 -> 0.0051609162 | G45: ='Balance sheet'!G44/'Balance sheet'!$G$34 -> 0 | H45: ='Balance sheet'!H44/'Balance sheet'!$H$34 -> 0
A46: Other financial liabilities | B46: ='Balance sheet'!B47/'Balance sheet'!$B$34 -> 0.00017495134 | C46: ='Balance sheet'!C47/'Balance sheet'!$C$34 -> 0 | D46: ='Balance sheet'!D47/'Balance sheet'!$D$34 -> 0 | E46: ='Balance sheet'!E47/'Balance sheet'!$E$34 -> 0 | F46: ='Balance sheet'!F47/'Balance sheet'!$F$34 -> 0.0099159177 | G46: ='Balance sheet'!G45/'Balance sheet'!$G$34 -> 0.18177606 | H46: ='Balance sheet'!H45/'Balance sheet'!$H$34 -> 0.16020677
...

Sheet Ratio Analysis
A2: Hindustan Zinc | B2: Formula | C2: 44286 | D2: 44651 | E2: 45016 | F2: 45382 | G2: 45747 | H2: 46112 | I2: 46477
A3: RATIO ANALYSIS | C3: Y | D3: Y | E3: Y | F3: Y | G3: Y | H3: Y | I3: Y
C4: Act | D4: Act | E4: Act | F4: Act | G4: Act | H4: Est | I4: Est
A6: Nunber of share | C6: =8460000/10000000 -> 0.846 | D6: =8450000/10000000 -> 0.845 | E6: =8450000/10000000 -> 0.845 | F6: =8450000/10000000 -> 0.845 | G6: =8450000/10000000 -> 0.845 | H6: =G6 -> 0.845 | I6: =H6 -> 0.845 | J6: News /Qualitative info | M6: LIQUIDITY RATIOS
A7: Dividend Per Share (DPS) | C7: 21.3 | D7: 18 | E7: 75.5 | F7: 13 | G7: 29 | H7: =H8/H6 -> 0 | I7: =I8/I6 -> 74.283618 | M7: Current Ratio
A8: Dividend Total | C8: =C6*C7 -> 18.0198 | D8: =D6*D7 -> 15.21 | E8: =E6*E7 -> 63.7975 | F8: =F6*F7 -> 10.985 | G8: =G6*G7 -> 24.505 | H8: =H25*'P&L '!G34 -> 0 | I8: =I25*'P&L '!H34 -> 62.769658 | J8: Pay out ratio*PAT | M8: Very high in 2021–22 showing excess liquidity
A9: Market Price of Share (MPS) | C9: 264.45 | D9: 310.15 | E9: 292.3 | F9: 292.3 | G9: 461.9 | H9: 461.9 | I9: 461.9 | M9: Sharp fall in 2023 indicates pressure on working capital
M10: Stabilizes near 1 in later years showing adequate liquidity
A11: Liquidity Ratio | M11: Quick Ratio
A12: CURRENT RATIO | B12: CURRENT ASSESTS/CURRENT LIABILITY | C12: ='Balance sheet'!B33/'Balance sheet'!B68 -> 3.1193499 | D12: ='Balance sheet'!C33/'Balance sheet'!C68 -> 3.9353462 | E12: ='Balance sheet'!D33/'Balance sheet'!D68 -> 0.84822094 | F12: ='Balance sheet'!E33/'Balance sheet'!E68 -> 1.1645605 | G12: ='Balance sheet'!F33/'Balance sheet'!F68 -> 1.0381284 | H12: ='Balance sheet'!G33/'Balance sheet'!G68 -> 1.0701852 | I12: ='Balance sheet'!H33/'Balance sheet'!H68 -> 1.07165 | M12: Follows same pattern as current ratio
A13: QUICK RATIO | B13: (CA-INVENTORIES)/CL | C13: =('Balance sheet'!B33-'Balance sheet'!B21)/'Balance sheet'!B68 -> 2.9384205 | D13: =('Balance sheet'!C33-'Balance sheet'!C21)/'Balance sheet'!C68 -> 3.6148671 | E13: =('Balance sheet'!D33-'Balance sheet'!D21)/'Balance sheet'!D68 -> 0.74153441 | F13: =('Balance sheet'!E33-'Balance sheet'!E21)/'Balance sheet'!E68 -> 0.98690158 | G13: =('Balance sheet'!F33-'Balance sheet'!F21)/'Balance sheet'!F68 -> 0.86945263 | H13: =('Balance sheet'!G33-'Balance sheet'!G21)/'Balance sheet'!G68 -> 1.0436463 | I13: =('Balance sheet'!H33-'Balance sheet'!H21)/'Balance sheet'!H68 -> 0.7771905 | M13: Decline after 2022 shows reduced liquid assets
A14: CASH RATIO | B14: (CASH+BANK+INVESTMENT)/CL | C14: =('Balance sheet'!B27+'Balance sheet'!B28+'Balance sheet'!B24)/'Balance sheet'!B68 -> 2.8355764 | D14: =('Balance sheet'!C27+'Balance sheet'!C28+'Balance sheet'!C24)/'Balance sheet'!C68 -> 3.4156547 | E14: =('Balance sheet'!D27+'Balance sheet'!D28+'Balance sheet'!D24)/'Balance sheet'!D68 -> 0.64527588 | F14: =('Balance sheet'!E27+'Balance sheet'!E28+'Balance sheet'!E24)/'Balance sheet'!E68 -> 0.92694401 | G14: =('Balance sheet'!F27+'Balance sheet'!F28+'Balance sheet'!F24)/'Balance sheet'!F68 -> 0.83275292 | H14: =('Balance sheet'!G27+'Balance sheet'!G28+'Balance sheet'!G24)/'Balance sheet'!G68 -> 1.0065461 | I14: =('Balance sheet'!H27+'Balance sheet'!H28+'Balance sheet'!H24)/'Balance sheet'!H68 -> 0.70054227 | M14: Later years indicate controlled short-term solvency
M15: Cash Ratio
A16: ACTIVITY RATIO | M16: Strong cash position initially
A17: DEBTOR TURNOVER RATIO | B17: TRADE REC/NET REVENUE * 365 | C17: ='Balance sheet'!B25/'P&L '!B8*365 -> 6.7142404 | D17: ='Balance sheet'!C25/'P&L '!C8*365 -> 9.0774575 | E17: ='Balance sheet'!D25/'P&L '!D8*365 -> 4.1686704 | F17: ='Balance sheet'!E25/'P&L '!E8*365 -> 2.0146357 | G17: ='Balance sheet'!F25/'P&L '!F8*365 -> 1.2924851 | H17: ='Balance sheet'!G25/'P&L '!G8*365 -> 4.6534978 | I17: ='Balance sheet'!H25/'P&L '!H8*365 -> 4.2413493 | M17: Falls after 2022 suggesting cash utilization
A18: CREDITOR TURNOVER RATIO | B18: TRADE PAY / TOTAL PURCHASE * 365 | C18: =('Balance sheet'!B59+'Balance sheet'!B61)/('P&L '!B11+'P&L '!B12)*365 -> 125.5678 | D18: =('Balance sheet'!C59+'Balance sheet'!C61)/('P&L '!C11+'P&L '!C12)*365 -> 121.56725 | E18: =('Balance sheet'!D59+'Balance sheet'!D61)/('P&L '!D11+'P&L '!D12)*365 -> 97.971462 | F18: =('Balance sheet'!E59+'Balance sheet'!E61)/('P&L '!E11+'P&L '!E12)*365 -> 120.86321 | G18: =('Balance sheet'!F59+'Balance sheet'!F61)/('P&L '!F11+'P&L '!F12)*365 -> 118.21602 | H18: =('Balance sheet'!G59+'Balance sheet'!G61)/('P&L '!G11+'P&L '!G12)*365 -> 116.83715 | I18: =('Balance sheet'!H59+'Balance sheet'!H61)/('P&L '!H11+'P&L '!H12)*365 -> 115.09102 | M18: Slight recovery later shows balanced cash management
A19: INVENTORY TURNOVER RATIO | B19: INVENTORY / COGS * 365 | C19: ='Balance sheet'!B21/'P&L '!B10*365 -> 109.963 | D19: ='Balance sheet'!C21/'P&L '!C10*365 -> 122.0416 | E19: ='Balance sheet'!D21/'P&L '!D10*365 -> 89.003405 | F19: ='Balance sheet'!E21/'P&L '!E10*365 -> 113.33065 | G19: ='Balance sheet'!F21/'P&L '!F10*365 -> 102.2823 | H19: ='Balance sheet'!G21/'P&L '!G10*365 -> 107.32419 | I19: ='Balance sheet'!H21/'P&L '!H10*365 -> 106.79643 | M19: ACTIVITY RATIOS
A20: OPERATING CYCLE | B20: DEBTOR TURNOVER DAY+ INVENTORY TURNOVER DAYS | C20: =C17+C19 -> 116.67724 | D20: =D17+D19 -> 131.11906 | E20: =E17+E19 -> 93.172075 | F20: =F17+F19 -> 115.34528 | G20: =G17+G19 -> 103.57479 | H20: =H17+H19 -> 111.97769 | I20: =I17+I19 -> 111.03778 | M20: Debtor Days
M21: Continuous decline across years
A22: PROFITABILITY RATIO | M22: Indicates faster receivable collection
A23: EARNING PER SHARE (EPS) | B23: PAT/NO OF SHARES | C23: ='P&L '!B34/'Ratio Analysis'!C6 -> 14364.066 | D23: ='P&L '!C34/'Ratio Analysis'!D6 -> 10788.166 | E23: ='P&L '!D34/'Ratio Analysis'!E6 -> 11461.538 | F23: ='P&L '!E34/'Ratio Analysis'!F6 -> 8176.3314 | G23: ='P&L '!F34/'Ratio Analysis'!G6 -> 11117.16 | H23: ='P&L '!G34/'Ratio Analysis'!H6 -> -1783.3545 | I23: ='P&L '!H34/'Ratio Analysis'!I6 -> 24368.536 | M23: Reflects improved credit management
A24: DIVIDEND PER SHARE (DPS) | B24: TOTAL DIVIDENDS/NO OF SHARE | C24: =C8/C6 -> 21.3 | D24: =D8/D6 -> 18 | E24: =E8/E6 -> 75.5 | F24: =F8/F6 -> 13 | G24: =G8/G6 -> 29 | H24: =H8/H6 -> 0 | I24: =I8/I6 -> 74.283618 | M24: Creditor Days
A25: PAY OUT RATIO | B25: DPS/EPS | C25: =C24/C23 -> 0.001482867 | D25: =D24/D23 -> 0.001668495 | E25: =E24/E23 -> 0.0065872483 | F25: =F24/F23 -> 0.0015899551 | G25: =G24/G23 -> 0.0026085799 | H25: =H24/H23 -> 0.0026085799 | I25: =I24/I23 -> 0.0026085799 | M25: Remains high and stable
A26: RENTENTION RATIO | B26: 1-PAYOUT RATIO | C26: =1-C25 -> 0.99851713 | D26: =1-D25 -> 0.99833151 | E26: =1-E25 -> 0.99341275 | F26: =1-F25 -> 0.99841004 | G26: =1-G25 -> 0.99739142 | H26: =1-H25 -> 1 | I26: =1-I25 -> 0.99695166 | M26: Shows strong supplier credit support
A27: EBITDA MARGIN | B27: EBIDTA/NET REVENUE | C27: ='P&L '!B19/'P&L '!B8 -> 0.71786507 | D27: ='P&L '!C19/'P&L '!C8 -> 0.54098645 | E27: ='P&L '!D19/'P&L '!D8 -> 0.50132243 | F27: ='P&L '!E19/'P&L '!E8 -> 0.45602165 | G27: ='P&L '!F19/'P&L '!F8 -> 0.49471868 | H27: ='P&L '!G19/'P&L '!G8 -> 0.49932118 | I27: ='P&L '!H19/'P&L '!H8 -> 0.49847408 | M27: Helps maintain good cash flow position
A28: EBIT MARGIN | B28: EBIT/NET REVENUE | C28: ='P&L '!B25/'P&L '!B8 -> 0.68560555 | D28: ='P&L '!C25/'P&L '!C8 -> 0.48200764 | E28: ='P&L '!D25/'P&L '!D8 -> 0.44466819 | F28: ='P&L '!E25/'P&L '!E8 -> 0.37077131 | G28: ='P&L '!F25/'P&L '!F8 -> 0.41430344 | H28: ='P&L '!G25/'P&L '!G8 -> -0.26667911 | I28: ='P&L '!H25/'P&L '!H8 -> 0.44320116 | M28: Inventory Days
A29: PBT MARGIN | B29: PBT/NET REVENUE | C29: ='P&L '!B29/'P&L '!B8 -> 0.66811653 | D29: ='P&L '!C29/'P&L '!C8 -> 0.4719347 | E29: ='P&L '!D29/'P&L '!D8 -> 0.43465977 | F29: ='P&L '!E29/'P&L '!E8 -> 0.33676376 | G29: ='P&L '!F29/'P&L '!F8 -> 0.3811628 | H29: ='P&L '!G29/'P&L '!G8 -> -0.49095329 | I29: ='P&L '!H29/'P&L '!H8 -> 0.42849461 | M29: Large fluctuations across years
A30: PAT MARGIN | B30: PAT/NET REVENUE | C30: ='P&L '!B34/'P&L '!B8 -> 0.55058674 | D30: ='P&L '!C34/'P&L '!C8 -> 0.31663772 | E30: ='P&L '!D34/'P&L '!D8 -> 0.2910856 | F30: ='P&L '!E34/'P&L '!E8 -> 0.24602949 | G30: ='P&L '!F34/'P&L '!F8 -> 0.28431343 | H30: ='P&L '!G34/'P&L '!G8 -> -0.38620532 | I30: ='P&L '!H34/'P&L '!H8 -> 0.32940612 | M30: Suggests changes in production levels or demand cycles
M31: Indicates inventory management instability
A32: SOLVENCY RATIO | M32: Operating Cycle
A33: DEBT TO EQUITY RATIOS | B33: (NON CURRENT BORROWINGS+SHORT TERM BORROWINGS)/TOTAL EQUITY | C33: =('Balance sheet'!B45)/'Balance sheet'!B40 -> 0.13344474 | D33: =('Balance sheet'!C45)/'Balance sheet'!C40 -> 0.0615793 | E33: =('Balance sheet'!D45)/'Balance sheet'!D40 -> 0.11599134 | F33: =('Balance sheet'!E45)/'Balance sheet'!E40 -> 0.27943402 | G33: =('Balance sheet'!F45)/'Balance sheet'!F40 -> 0.44949722 | H33: =('Balance sheet'!G45)/'Balance sheet'!G40 -> 0.50680826 | I33: =('Balance sheet'!H45)/'Balance sheet'!H40 -> 0.18515136 | M33: Moves mainly with inventory changes
A34: INTEREST COVERAGE RATIO | B34: EBIT/FINANCE COST | C34: ='P&L '!B25/'P&L '!B27 -> 39.202073 | D34: ='P&L '!C25/'P&L '!C27 -> 47.851724 | E34: ='P&L '!D25/'P&L '!D27 -> 44.429429 | F34: ='P&L '!E25/'P&L '!E27 -> 10.902618 | G34: ='P&L '!F25/'P&L '!F27 -> 12.50137 | H34: ='P&L '!G25/'P&L '!G27 -> -1.1890763 | I34: ='P&L '!H25/'P&L '!H27 -> 30.136311 | M34: Longer cycle in some years due to stock build-up
M35: Overall working capital efficiency depends on inventory control
A36: RETURN RATIO
A37: RETURN ON EQUITY | B37: PAT/TOTAL EQUITY | C37: ='P&L '!B34/'Balance sheet'!B40 -> 0.37607155 | D37: ='P&L '!C34/'Balance sheet'!C40 -> 0.2659199 | E37: ='P&L '!D34/'Balance sheet'!D40 -> 0.74891741 | F37: ='P&L '!E34/'Balance sheet'!E40 -> 0.45468904 | G37: ='P&L '!F34/'Balance sheet'!F40 -> 0.70493772 | H37: ='P&L '!G34/'Balance sheet'!G40 -> -0.12750031 | I37: ='P&L '!H34/'Balance sheet'!H40 -> 0.63648215
A38: CAPITAL EMPLOYED | B38: LONG TERM BORROWINGS + SHORT TERM BORROWINGS + TOTAL EQUITY | C38: ='Balance sheet'!B45+'Balance sheet'!B40 -> 36625 | D38: ='Balance sheet'!C45+'Balance sheet'!C40 -> 36392 | E38: ='Balance sheet'!D45+'Balance sheet'!D40 -> 14432 | F38: ='Balance sheet'!E45+'Balance sheet'!E40 -> 19441 | G38: ='Balance sheet'!F45+'Balance sheet'!F40 -> 19316 | H38: ='Balance sheet'!G45+'Balance sheet'!G40 -> 17809.065 | I38: ='Balance sheet'!H45+'Balance sheet'!H40 -> 19441 | M38: PROFITABILITY RATIOS
A39: ROCE (RETURN ON CAPITAL EMP) | B39: EBIT/CAPITAL EMPLOYED | C39: ='P&L '!B25/'Ratio Analysis'!C38 -> 0.41316041 | D39: ='P&L '!C25/'Ratio Analysis'!D38 -> 0.38132007 | E39: ='P&L '!D25/'Ratio Analysis'!E38 -> 1.0251524 | F39: ='P&L '!E25/'Ratio Analysis'!F38 -> 0.53556916 | G39: ='P&L '!F25/'Ratio Analysis'!G38 -> 0.7086871 | H39: ='P&L '!G25/'Ratio Analysis'!H38 -> -0.058428401 | I39: ='P&L '!H25/'Ratio Analysis'!I38 -> 0.41316041 | M39: EPS
A40: RETURN ON ASSESTS (ROA) | B40: PAT/TOTAL ASSESTS | C40: ='P&L '!B34/'Balance sheet'!B34 -> 0.26575109 | D40: ='P&L '!C34/'Balance sheet'!C34 -> 0.20407432 | E40: ='P&L '!D34/'Balance sheet'!D34 -> 0.27307074 | F40: ='P&L '!E34/'Balance sheet'!E34 -> 0.20383537 | G40: ='P&L '!F34/'Balance sheet'!F34 -> 0.2723688 | H40: ='P&L '!G34/'Balance sheet'!G34 -> -0.045730321 | I40: ='P&L '!H34/'Balance sheet'!H34 -> 0.55073184 | M40: Declines from 2021 to 2024
M41: Improves in 2025
A42: VALUATION RATIO | M42: Negative in 2026 then rises again
...

Sheet Revenue model
A2: Hindustan Zinc | B2: 44286 | C2: 44651 | D2: 45016 | E2: 45382 | F2: 45747 | G2: 46112 | H2: 46477
A3: REVENUE MODEL | B3: Y | C3: Y | D3: Y | E3: Y | F3: Y | G3: Y | H3: Y
A4: (in INR Crores) | B4: Act | C4: Act | D4: Act | E4: Act | F4: Act | G4: Est | H4: Est
J5: Total revenue shows an overall upward trend → core demand is growing long term.
A6: Sale of scrap and residuals | B6: 387 | C6: 319 | D6: 410 | E6: 482 | F6: 662 | G6: =G7*F6+F6 -> 741.44 | H6: =H78*G6+G6 -> 741.44 | J6: Scrap sales increase steadily → efficient resource utilization and cost recovery.
A7: % change as YOY | C7: =C6/B6-1 -> -0.17571059 | D7: =D6/C6-1 -> 0.28526646 | E7: =E6/D6-1 -> 0.17560976 | F7: =F6/E6-1 -> 0.37344398 | G7: 0.12 | H7: 0.105 | J7: Export incentives fluctuate → dependent on policy and external trade conditions.
J8: “Other income” grows gradually → additional revenue streams supporting total income
A9: Export incentives | B9: 80 | C9: 205 | D9: 235 | E9: 198 | F9: 183 | G9: =G10*F9+F9 -> 2928 | H9: =H10*G9+G9 -> 61488 | J9: One dip year appears → likely commodity price or volume cycle, not structural weakness.
A10: % change as YOY | C10: =C9/B9-1 -> 1.5625 | D10: =D9/C9-1 -> 0.14634146 | E10: =E9/D9-1 -> -0.15744681 | F10: =F9/E9-1 -> -0.075757576 | G10: 15 | H10: 20 | J10: Forecast years show strong growth → assumption of higher production or price improvement.
A12: Others (unclaimed amount, carbon credits, etc.) | B12: 91 | C12: 126 | D12: 181 | E12: 170 | F12: 197 | G12: =G13*F12+F12 -> 232.46 | H12: =H13*G12+G12 -> 281.2766
A13: % change as YOY | C13: =C12/B12-1 -> 0.38461538 | D13: =D12/C12-1 -> 0.43650794 | E13: =E12/D12-1 -> -0.060773481 | F13: =F12/E12-1 -> 0.15882353 | G13: 0.18 | H13: 0.21
